Workbook

Sheet Planilha1
A1: SEI | B1: GESTOR | C1: OBJETO | D1: EMPRESA | E1: MUNICIPIO | F1: FISCAL NOMEADO | G1: STATUS_original | H1: REGIÃO | I1: STATUS
A2: 150001/012862/2022 | B2: =IFERROR(VLOOKUP(TRIM(A2),[1]Medições!$B$2:$I$48,8,FALSE),VLOOKUP(TRIM(A2),[1]PROBLEMAS!$B$2:$I$122,8,FALSE)) -> AIMAR FILHO | C2: =VLOOKUP(TRIM(Tabela2[[#This Row],[SEI]]),Tabela3[[Processo SEI]:[Objeto]],5,FALSE) -> PROJETOS E OBRAS PARA REFORMA DA SEDE DO TRE-RJ | D2: CONCREJATO | E2: RIO DE JANEIRO | G2: ACEITE DEFINITIVO | H2: ESPECIAIS | I2: =IFERROR(VLOOKUP(TRIM(Tabela2[[#This Row],[SEI]]),[1]Medições!$B$2:$H$48,7,FALSE),Tabela2[[#This Row],[STATUS_original]]) -> ACEITE DEFINITIVO
A3: E-17/026/1514/2019 | B3: =IFERROR(VLOOKUP(TRIM(A3),[1]Medições!$B$2:$I$48,8,FALSE),VLOOKUP(TRIM(A3),[1]PROBLEMAS!$B$2:$I$122,8,FALSE)) -> AIMAR FILHO | C3: =VLOOKUP(TRIM(Tabela2[[#This Row],[SEI]]),Tabela3[[Processo SEI]:[Objeto]],5,FALSE) -> PROJETO EXECUTIVO E OBRA DE COZINHA INDUSTRIAL E SEDE DA 1ª COMPANHIA DO CFAP – RIO DE JANEIRO | D3: VCE | E3: RIO DE JANEIRO | G3: DISTRATO | H3: ESPECIAIS | I3: =IFERROR(VLOOKUP(TRIM(Tabela2[[#This Row],[SEI]]),[1]Medições!$B$2:$H$48,7,FALSE),Tabela2[[#This Row],[STATUS_original]]) -> DISTRATO
A4: 170026/000230/2022 | B4: =IFERROR(VLOOKUP(TRIM(A4),[1]Medições!$B$2:$I$48,8,FALSE),VLOOKUP(TRIM(A4),[1]PROBLEMAS!$B$2:$I$122,8,FALSE)) -> CARLOS FERNANDES | C4: =VLOOKUP(TRIM(Tabela2[[#This Row],[SEI]]),Tabela3[[Processo SEI]:[Objeto]],5,FALSE) -> CANALIZAÇÃO DO CANAL ABEL - NOVA IGUAÇU E QUEIMADOS | D4: DRATEC | E4: NOVA IGUAÇÚ | F4: ARLINDO BASILIO / OSVALDO NETO | G4: #CONCLUIDA | H4: BX | I4: =IFERROR(VLOOKUP(TRIM(Tabela2[[#This Row],[SEI]]),[1]Medições!$B$2:$H$48,7,FALSE),Tabela2[[#This Row],[STATUS_original]]) -> #CONCLUIDA
A5: 460001/000821/2023 | B5: =IFERROR(VLOOKUP(TRIM(A5),[1]Medições!$B$2:$I$48,8,FALSE),VLOOKUP(TRIM(A5),[1]PROBLEMAS!$B$2:$I$122,8,FALSE)) -> CARLOS FERNANDES | C5: =VLOOKUP(TRIM(Tabela2[[#This Row],[SEI]]),Tabela3[[Processo SEI]:[Objeto]],5,FALSE) -> REVESTIMENTO ASFÁLTICO E DRENAGEM NO 2° DISTRITO (Lote 1) – DUQUE DE CAXIAS/RJ (#FUNDO SOBERANO) | D5: LYTORANEA | E5: DUQUE DE CAXIAS | F5: NICHOLAS TAVARES / ARLINDO BASILIO | G5: #CONCLUIDA | H5: BX | I5: =IFERROR(VLOOKUP(TRIM(Tabela2[[#This Row],[SEI]]),[1]Medições!$B$2:$H$48,7,FALSE),Tabela2[[#This Row],[STATUS_original]]) -> #CONCLUIDA
A6: 460001/000827/2023 | B6: =IFERROR(VLOOKUP(TRIM(A6),[1]Medições!$B$2:$I$48,8,FALSE),VLOOKUP(TRIM(A6),[1]PROBLEMAS!$B$2:$I$122,8,FALSE)) -> CARLOS FERNANDES | C6: =VLOOKUP(TRIM(Tabela2[[#This Row],[SEI]]),Tabela3[[Processo SEI]:[Objeto]],5,FALSE) -> REVESTIMENTO ASFÁLTICO E DRENAGEM NO 2° DISTRITO (Lote 2) – DUQUE DE CAXIAS/RJ (#FUNDO SOBERANO) | D6: ÔMEGA | E6: DUQUE DE CAXIAS | F6: NICHOLAS TAVARES / OSVALDO NETO | G6: #CONCLUIDA | H6: BX | I6: =IFERROR(VLOOKUP(TRIM(Tabela2[[#This Row],[SEI]]),[1]Medições!$B$2:$H$48,7,FALSE),Tabela2[[#This Row],[STATUS_original]]) -> #CONCLUIDA
A7: 330018/001213/2022 | B7: =IFERROR(VLOOKUP(TRIM(A7),[1]Medições!$B$2:$I$48,8,FALSE),VLOOKUP(TRIM(A7),[1]PROBLEMAS!$B$2:$I$122,8,FALSE)) -> CARLOS FERNANDES | C7: =VLOOKUP(TRIM(Tabela2[[#This Row],[SEI]]),Tabela3[[Processo SEI]:[Objeto]],5,FALSE) -> PONTE EM CONCRETO PROTENDIDO COM DRENAGEM – BELFORD ROXO/RJ | D7: SEEL | E7: BELFORD ROXO | F7: NICHOLAS TAVARES / OTAVIO FEITOSA | G7: #CONCLUIDA | H7: BX | I7: =IFERROR(VLOOKUP(TRIM(Tabela2[[#This Row],[SEI]]),[1]Medições!$B$2:$H$48,7,FALSE),Tabela2[[#This Row],[STATUS_original]]) -> #CONCLUIDA
A8: 330018/000737/2022 | B8: =IFERROR(VLOOKUP(TRIM(A8),[1]Medições!$B$2:$I$48,8,FALSE),VLOOKUP(TRIM(A8),[1]PROBLEMAS!$B$2:$I$122,8,FALSE)) -> CARLOS FERNANDES | C8: =VLOOKUP(TRIM(Tabela2[[#This Row],[SEI]]),Tabela3[[Processo SEI]:[Objeto]],5,FALSE) -> PROJETO, DRENAGEM E INFRAESTRUTURA - MENDES/RJ | D8: CMHR | E8: MENDES | F8: JOÃO RODRIGUES / LEANDRO RAMOS | G8: #CONCLUIDA | H8: SL | I8: =IFERROR(VLOOKUP(TRIM(Tabela2[[#This Row],[SEI]]),[1]Medições!$B$2:$H$48,7,FALSE),Tabela2[[#This Row],[STATUS_original]]) -> #CONCLUIDA
A9: 330018/000931/2021 | B9: =IFERROR(VLOOKUP(TRIM(A9),[1]Medições!$B$2:$I$48,8,FALSE),VLOOKUP(TRIM(A9),[1]PROBLEMAS!$B$2:$I$122,8,FALSE)) -> CARLOS FERNANDES | C9: =VLOOKUP(TRIM(Tabela2[[#This Row],[SEI]]),Tabela3[[Processo SEI]:[Objeto]],5,FALSE) -> REVITALIZAÇÃO – AV. DOM PEDRO II – PORTO REAL-RJ | D9: COMAL | E9: PORTO REAL | F9: JOÃO RODRIGUES / LEANDRO RAMOS | G9: #CONCLUIDA | H9: SL | I9: =IFERROR(VLOOKUP(TRIM(Tabela2[[#This Row],[SEI]]),[1]Medições!$B$2:$H$48,7,FALSE),Tabela2[[#This Row],[STATUS_original]]) -> #CONCLUIDA
A10: 170026/003250/2021 | B10: =IFERROR(VLOOKUP(TRIM(A10),[1]Medições!$B$2:$I$48,8,FALSE),VLOOKUP(TRIM(A10),[1]PROBLEMAS!$B$2:$I$122,8,FALSE)) -> CARLOS FERNANDES | C10: =VLOOKUP(TRIM(Tabela2[[#This Row],[SEI]]),Tabela3[[Processo SEI]:[Objeto]],5,FALSE) -> RECAPEAMENTO, PAVIMENTAÇÃO E CONTENÇÃO – BARRA MANSA-RJ | D10: LYTORANEA | E10: BARRA MANSA | F10: LUCIANA POSTIÇO / LEANDRO RAMOS | G10: #CONCLUIDA | H10: SL | I10: =IFERROR(VLOOKUP(TRIM(Tabela2[[#This Row],[SEI]]),[1]Medições!$B$2:$H$48,7,FALSE),Tabela2[[#This Row],[STATUS_original]]) -> #CONCLUIDA
A11: E-17/001/2008/2014 | B11: =IFERROR(VLOOKUP(TRIM(A11),[1]Medições!$B$2:$I$48,8,FALSE),VLOOKUP(TRIM(A11),[1]PROBLEMAS!$B$2:$I$122,8,FALSE)) -> CARLOS FERNANDES | C11: =VLOOKUP(TRIM(Tabela2[[#This Row],[SEI]]),Tabela3[[Processo SEI]:[Objeto]],5,FALSE) -> MICRODRENAGEM E PAVIMENTAÇÃO NO BAIRRO AUSTIN - NOVA IGUAÇU | D11: HYDRA | E11: NOVA IGUAÇÚ | F11: NICHOLAS TAVARES | G11: ACEITE DEFINITIVO | H11: BX | I11: =IFERROR(VLOOKUP(TRIM(Tabela2[[#This Row],[SEI]]),[1]Medições!$B$2:$H$48,7,FALSE),Tabela2[[#This Row],[STATUS_original]]) -> ACEITE DEFINITIVO
A12: 330018/000480/2022 | B12: =IFERROR(VLOOKUP(TRIM(A12),[1]Medições!$B$2:$I$48,8,FALSE),VLOOKUP(TRIM(A12),[1]PROBLEMAS!$B$2:$I$122,8,FALSE)) -> CARLOS FERNANDES | C12: =VLOOKUP(TRIM(Tabela2[[#This Row],[SEI]]),Tabela3[[Processo SEI]:[Objeto]],5,FALSE) -> CONTENÇÃO, DRENAGEM E ESTABILIZAÇÃO – SÃO JOSÉ DE UBÁ/RJ | D12: CTESA | E12: SÃO JOSÉ DE UBÁ | F12: CAIO / JOÃO RODRIGUES | G12: ACEITE DEFINITIVO | H12: NT | I12: =IFERROR(VLOOKUP(TRIM(Tabela2[[#This Row],[SEI]]),[1]Medições!$B$2:$H$48,7,FALSE),Tabela2[[#This Row],[STATUS_original]]) -> ACEITE DEFINITIVO
A13: 330018/000982/2021 | B13: =IFERROR(VLOOKUP(TRIM(A13),[1]Medições!$B$2:$I$48,8,FALSE),VLOOKUP(TRIM(A13),[1]PROBLEMAS!$B$2:$I$122,8,FALSE)) -> CARLOS FERNANDES | C13: =VLOOKUP(TRIM(Tabela2[[#This Row],[SEI]]),Tabela3[[Processo SEI]:[Objeto]],5,FALSE) -> ESTABILIZAÇÃO DE ENCOSTA – AV. FERROVIÁRIOS, NOVA FRIBURGO | D13: SOLOTESTE | E13: NOVA FRIBURGO | F13: CAIO / ARLINDO BASILIO | G13: ACEITE DEFINITIVO | H13: NT | I13: =IFERROR(VLOOKUP(TRIM(Tabela2[[#This Row],[SEI]]),[1]Medições!$B$2:$H$48,7,FALSE),Tabela2[[#This Row],[STATUS_original]]) -> ACEITE DEFINITIVO
A14: 170026/000538/2022 | B14: =IFERROR(VLOOKUP(TRIM(A14),[1]Medições!$B$2:$I$48,8,FALSE),VLOOKUP(TRIM(A14),[1]PROBLEMAS!$B$2:$I$122,8,FALSE)) -> CARLOS FERNANDES | C14: =VLOOKUP(TRIM(Tabela2[[#This Row],[SEI]]),Tabela3[[Processo SEI]:[Objeto]],5,FALSE) -> CONTENÇÃO E DRENAGEM EM CASTELÂNEA, PETRÓPOLIS | D14: CONSÓRCIO ECONORTE GEOSONDA | E14: PETROPOLIS | F14: JEHNIFFER PIRES / WASHINGTON | G14: CONCLUIDA | H14: BX | I14: =IFERROR(VLOOKUP(TRIM(Tabela2[[#This Row],[SEI]]),[1]Medições!$B$2:$H$48,7,FALSE),Tabela2[[#This Row],[STATUS_original]]) -> CONCLUIDA
A15: 330018/001303/2022 | B15: =IFERROR(VLOOKUP(TRIM(A15),[1]Medições!$B$2:$I$48,8,FALSE),VLOOKUP(TRIM(A15),[1]PROBLEMAS!$B$2:$I$122,8,FALSE)) -> CARLOS FERNANDES | C15: =VLOOKUP(TRIM(Tabela2[[#This Row],[SEI]]),Tabela3[[Processo SEI]:[Objeto]],5,FALSE) -> DRENAGEM PLUVIAL E PAVIMENTAÇÃO NO BAIRRO MIGUEL COUTO – NOVA IGUAÇU/RJ | D15: CONSTRUTEC | E15: NOVA IGUAÇÚ | F15: NICHOLAS TAVARES / OTAVIO FEITOSA | G15: CONCLUIDA | H15: BX | I15: =IFERROR(VLOOKUP(TRIM(Tabela2[[#This Row],[SEI]]),[1]Medições!$B$2:$H$48,7,FALSE),Tabela2[[#This Row],[STATUS_original]]) -> CONCLUIDA
... A32: 330018/000333/2022 | B32: =IFERROR(VLOOKUP(TRIM(A32),[1]Medições!$B$2:$I$48,8,FALSE),VLOOKUP(TRIM(A32),[1]PROBLEMAS!$B$2:$I$122,8,FALSE)) -> CARLOS FERNANDES | C32: =VLOOKUP(TRIM(Tabela2[[#This Row],[SEI]]),Tabela3[[Processo SEI]:[Objeto]],5,FALSE) -> RECAPEAMENTO DE LOGRADOUROS EM MAGÉ – RJ | D32: GRAVISA | E32: MAGÉ | F32: ARLINDO BASILIO / OSVALDO NETO | G32: SUSPENSA | H32: BX | I32: =IFERROR(VLOOKUP(TRIM(Tabela2[[#This Row],[SEI]]),[1]Medições!$B$2:$H$48,7,FALSE),Tabela2[[#This Row],[STATUS_original]]) -> SUSPENSA
A33: E-17/026/0056/2020 | B33: =IFERROR(VLOOKUP(TRIM(A33),[1]Medições!$B$2:$I$48,8,FALSE),VLOOKUP(TRIM(A33),[1]PROBLEMAS!$B$2:$I$122,8,FALSE)) -> ERICK HYLARIO | C33: =VLOOKUP(TRIM(Tabela2[[#This Row],[SEI]]),Tabela3[[Processo SEI]:[Objeto]],5,FALSE) -> HOSPITAL COVID-19, NO MUNICÍPIO DE NOVA IGUAÇU | D33: BIG FARM | E33: NOVA IGUAÇU | G33: ACEITE DEFINITIVO | H33: ESPECIAIS | I33: =IFERROR(VLOOKUP(TRIM(Tabela2[[#This Row],[SEI]]),[1]Medições!$B$2:$H$48,7,FALSE),Tabela2[[#This Row],[STATUS_original]]) -> ACEITE DEFINITIVO
A34: 330001/000097/2024 | B34: =IFERROR(VLOOKUP(TRIM(A34),[1]Medições!$B$2:$I$48,8,FALSE),VLOOKUP(TRIM(A34),[1]PROBLEMAS!$B$2:$I$122,8,FALSE)) -> ERICK HYLARIO | C34: =VLOOKUP(TRIM(Tabela2[[#This Row],[SEI]]),Tabela3[[Processo SEI]:[Objeto]],5,FALSE) -> CONCLUSÃO DAS OBRAS DA NOVA SEDE DO MIS – RIO DE JANEIRO | D34: CONS.COPACABANA | E34: RIO DE JANEIRO | F34: OSVALDO NETO / DANRLEI GOMES | G34: EXECUÇÃO | H34: ESPECIAIS | I34: =IFERROR(VLOOKUP(TRIM(Tabela2[[#This Row],[SEI]]),[1]Medições!$B$2:$H$48,7,FALSE),Tabela2[[#This Row],[STATUS_original]]) -> EXECUÇÃO
A35: 460001/001918/2023 | B35: =IFERROR(VLOOKUP(TRIM(A35),[1]Medições!$B$2:$I$48,8,FALSE),VLOOKUP(TRIM(A35),[1]PROBLEMAS!$B$2:$I$122,8,FALSE)) -> ERICK HYLARIO | C35: =VLOOKUP(TRIM(Tabela2[[#This Row],[SEI]]),Tabela3[[Processo SEI]:[Objeto]],5,FALSE) -> REFAZIMENTO DAS FACHADAS DO MIS - NOVA SEDE - 2023 | D35: COPACABANA R2X/TANGRAM | E35: RIO DE JANEIRO | F35: HIGOR MARTINS / DANRLEI GOMES | G35: EXECUÇÃO | H35: ESPECIAIS | I35: =IFERROR(VLOOKUP(TRIM(Tabela2[[#This Row],[SEI]]),[1]Medições!$B$2:$H$48,7,FALSE),Tabela2[[#This Row],[STATUS_original]]) -> EXECUÇÃO
A36: 330001/000247/2025 | B36: =IFERROR(VLOOKUP(TRIM(A36),[1]Medições!$B$2:$I$48,8,FALSE),VLOOKUP(TRIM(A36),[1]PROBLEMAS!$B$2:$I$122,8,FALSE)) -> ERICK HYLARIO | C36: =VLOOKUP(TRIM(Tabela2[[#This Row],[SEI]]),Tabela3[[Processo SEI]:[Objeto]],5,FALSE) -> PAINÉIS DE MARCENARIA DO MIS | D36: FAB MIX CONCRETOS | E36: RIO DE JANEIRO | F36: OSVALDO NETO / HIGOR MARTINS | G36: EXECUÇÃO | H36: ESPECIAIS | I36: =IFERROR(VLOOKUP(TRIM(Tabela2[[#This Row],[SEI]]),[1]Medições!$B$2:$H$48,7,FALSE),Tabela2[[#This Row],[STATUS_original]]) -> EXECUÇÃO
A37: 330001/000414/2024 | B37: =IFERROR(VLOOKUP(TRIM(A37),[1]Medições!$B$2:$I$48,8,FALSE),VLOOKUP(TRIM(A37),[1]PROBLEMAS!$B$2:$I$122,8,FALSE)) -> ERICK HYLARIO | C37: =VLOOKUP(TRIM(Tabela2[[#This Row],[SEI]]),Tabela3[[Processo SEI]:[Objeto]],5,FALSE) -> RECUPERAÇÃO DE EQUIPAMENTOS DO TELEFÉRICO DO ALEMÃO - RJ | D37: MPE | E37: RIO DE JANEIRO | F37: HIGOR MARTINS / DANRLEI GOMES | G37: EXECUÇÃO | H37: ESPECIAIS | I37: =IFERROR(VLOOKUP(TRIM(Tabela2[[#This Row],[SEI]]),[1]Medições!$B$2:$H$48,7,FALSE),Tabela2[[#This Row],[STATUS_original]]) -> EXECUÇÃO
A38: 460001/000779/2023 | B38: =IFERROR(VLOOKUP(TRIM(A38),[1]Medições!$B$2:$I$48,8,FALSE),VLOOKUP(TRIM(A38),[1]PROBLEMAS!$B$2:$I$122,8,FALSE)) -> ERICK HYLARIO | C38: =VLOOKUP(TRIM(Tabela2[[#This Row],[SEI]]),Tabela3[[Processo SEI]:[Objeto]],5,FALSE) -> RECUPERAÇÃO DO TÚNEL EXTRAVASOR EM PETRÓPOLIS | D38: ENGEPRAT | E38: PETRÓPOLIS | G38: ACEITE PROVISORIO | H38: ESPECIAIS | I38: =IFERROR(VLOOKUP(TRIM(Tabela2[[#This Row],[SEI]]),[1]Medições!$B$2:$H$48,7,FALSE),Tabela2[[#This Row],[STATUS_original]]) -> ACEITE PROVISORIO
A39: 170026/000233/2022 | B39: =IFERROR(VLOOKUP(TRIM(A39),[1]Medições!$B$2:$I$48,8,FALSE),VLOOKUP(TRIM(A39),[1]PROBLEMAS!$B$2:$I$122,8,FALSE)) -> ERICK HYLARIO | C39: =VLOOKUP(TRIM(Tabela2[[#This Row],[SEI]]),Tabela3[[Processo SEI]:[Objeto]],5,FALSE) -> CONCLUSÃO DO HOSPITAL DE ONCOLOGIA EM NOVA FRIBURGO | D39: MPE | E39: NOVA FRIBURGO | F39: DANRLEI GOMES / IZADORA COE | G39: EXECUÇÃO | H39: ESPECIAIS | I39: =IFERROR(VLOOKUP(TRIM(Tabela2[[#This Row],[SEI]]),[1]Medições!$B$2:$H$48,7,FALSE),Tabela2[[#This Row],[STATUS_original]]) -> EXECUÇÃO
A40: 170026/001756/2021 | B40: =IFERROR(VLOOKUP(TRIM(A40),[1]Medições!$B$2:$I$48,8,FALSE),VLOOKUP(TRIM(A40),[1]PROBLEMAS!$B$2:$I$122,8,FALSE)) -> ERICK HYLARIO | C40: =VLOOKUP(TRIM(Tabela2[[#This Row],[SEI]]),Tabela3[[Processo SEI]:[Objeto]],5,FALSE) -> CONCLUSÃO DAS OBRAS DO MUSEU DA IMAGEM E DO SOM - COPACABANA - RJ | D40: MPE | E40: RIO DE JANEIRO | G40: DISTRATO | H40: ESPECIAIS | I40: =IFERROR(VLOOKUP(TRIM(Tabela2[[#This Row],[SEI]]),[1]Medições!$B$2:$H$48,7,FALSE),Tabela2[[#This Row],[STATUS_original]]) -> DISTRATO
A41: 170026/001757/2021 | B41: =IFERROR(VLOOKUP(TRIM(A41),[1]Medições!$B$2:$I$48,8,FALSE),VLOOKUP(TRIM(A41),[1]PROBLEMAS!$B$2:$I$122,8,FALSE)) -> ERICK HYLARIO | C41: =VLOOKUP(TRIM(Tabela2[[#This Row],[SEI]]),Tabela3[[Processo SEI]:[Objeto]],5,FALSE) -> OBRAS DE ILUMINAÇÃO E ACABAMENTOS - MUSEU DA IMAGEM E DO SOM - COPACABANA - RJ | D41: MPE | E41: RIO DE JANEIRO | G41: DISTRATO | H41: ESPECIAIS | I41: =IFERROR(VLOOKUP(TRIM(Tabela2[[#This Row],[SEI]]),[1]Medições!$B$2:$H$48,7,FALSE),Tabela2[[#This Row],[STATUS_original]]) -> DISTRATO
A42: 170026/003470/2021 | B42: =IFERROR(VLOOKUP(TRIM(A42),[1]Medições!$B$2:$I$48,8,FALSE),VLOOKUP(TRIM(A42),[1]PROBLEMAS!$B$2:$I$122,8,FALSE)) -> ERICK HYLARIO | C42: =VLOOKUP(TRIM(Tabela2[[#This Row],[SEI]]),Tabela3[[Processo SEI]:[Objeto]],5,FALSE) -> RECUPERAÇÃO DAS ESTAÇÕES DO TELEFÉRICO DO ALEMÃO – RJ | D42: PETROPUMP | E42: RIO DE JANEIRO | F42: HIGOR MARTINS / DANRLEI GOMES | G42: ACEITE PROVISORIO | H42: ESPECIAIS | I42: =IFERROR(VLOOKUP(TRIM(Tabela2[[#This Row],[SEI]]),[1]Medições!$B$2:$H$48,7,FALSE),Tabela2[[#This Row],[STATUS_original]]) -> ACEITE PROVISORIO
A43: 170026/000214/2022 | B43: =IFERROR(VLOOKUP(TRIM(A43),[1]Medições!$B$2:$I$48,8,FALSE),VLOOKUP(TRIM(A43),[1]PROBLEMAS!$B$2:$I$122,8,FALSE)) -> ERICK HYLARIO | C43: =VLOOKUP(TRIM(Tabela2[[#This Row],[SEI]]),Tabela3[[Processo SEI]:[Objeto]],5,FALSE) -> AQUISIÇÃO DE EQUIPAMENTOS PARA TELEFÉRICO DO ALEMÃO – RJ | D43: POMA | E43: RIO DE JANEIRO | G43: EXECUÇÃO | H43: ESPECIAIS | I43: =IFERROR(VLOOKUP(TRIM(Tabela2[[#This Row],[SEI]]),[1]Medições!$B$2:$H$48,7,FALSE),Tabela2[[#This Row],[STATUS_original]]) -> EXECUÇÃO
A44: 330018/000190/2022 | B44: =IFERROR(VLOOKUP(TRIM(A44),[1]Medições!$B$2:$I$48,8,FALSE),VLOOKUP(TRIM(A44),[1]PROBLEMAS!$B$2:$I$122,8,FALSE)) -> GISELLE G. FONSECA | C44: =VLOOKUP(TRIM(Tabela2[[#This Row],[SEI]]),Tabela3[[Processo SEI]:[Objeto]],5,FALSE) -> MACRODRENAGEM DO CANAL VILA CANAAN - DUQUE DE CAXIAS | D44: BRASFORM | E44: DUQUE DE CAXIAS | F44: CAIO / LUIZ FILHO | G44: CONCLUIDA | H44: BX | I44: =IFERROR(VLOOKUP(TRIM(Tabela2[[#This Row],[SEI]]),[1]Medições!$B$2:$H$48,7,FALSE),Tabela2[[#This Row],[STATUS_original]]) -> CONCLUIDA
A45: 170026/002777/2021 | B45: =IFERROR(VLOOKUP(TRIM(A45),[1]Medições!$B$2:$I$48,8,FALSE),VLOOKUP(TRIM(A45),[1]PROBLEMAS!$B$2:$I$122,8,FALSE)) -> GISELLE G. FONSECA | C45: =VLOOKUP(TRIM(Tabela2[[#This Row],[SEI]]),Tabela3[[Processo SEI]:[Objeto]],5,FALSE) -> PROJETO EXECUTIVO E EXECUÇÃO DE OBRAS DE DRENAGEM, PAVIMENTAÇÃO E INFRAESTRUTURA – SÃO JOSÉ – JAPERI/RJ | D45: CONS. SÃO JOSÉ - HY./ MED. | E45: JAPERI | F45: OSVALDO NETO | G45: DISTRATO | H45: BX | I45: =IFERROR(VLOOKUP(TRIM(Tabela2[[#This Row],[SEI]]),[1]Medições!$B$2:$H$48,7,FALSE),Tabela2[[#This Row],[STATUS_original]]) -> DISTRATO
A46: 170026/001611/2020 | B46: =IFERROR(VLOOKUP(TRIM(A46),[1]Medições!$B$2:$I$48,8,FALSE),VLOOKUP(TRIM(A46),[1]PROBLEMAS!$B$2:$I$122,8,FALSE)) -> GISELLE G. FONSECA | C46: =VLOOKUP(TRIM(Tabela2[[#This Row],[SEI]]),Tabela3[[Processo SEI]:[Objeto]],5,FALSE) -> REVITALIZAÇÃO DA CICLOVIA E CALÇADA DA ORLA DA PRAIA DO SACO - MANGARATIBA/RJ | D46: GONÇALVES NEVES | E46: MANGARATIBA | F46: OSVALDO NETO | G46: CONCLUIDA | H46: BX | I46: =IFERROR(VLOOKUP(TRIM(Tabela2[[#This Row],[SEI]]),[1]Medições!$B$2:$H$48,7,FALSE),Tabela2[[#This Row],[STATUS_original]]) -> CONCLUIDA
A47: 330018/001315/2022 | B47: =IFERROR(VLOOKUP(TRIM(A47),[1]Medições!$B$2:$I$48,8,FALSE),VLOOKUP(TRIM(A47),[1]PROBLEMAS!$B$2:$I$122,8,FALSE)) -> GISELLE G. FONSECA | C47: =VLOOKUP(TRIM(Tabela2[[#This Row],[SEI]]),Tabela3[[Processo SEI]:[Objeto]],5,FALSE) -> IMPLANTAÇÃO DE CICLOVIA E CALÇADA NA ESTRADA ZUMBI – NOVA IGUAÇU/RJ | D47: HYDRA | E47: NOVA IGUAÇÚ | F47: MAURÍCIO | G47: DISTRATO | H47: BX | I47: =IFERROR(VLOOKUP(TRIM(Tabela2[[#This Row],[SEI]]),[1]Medições!$B$2:$H$48,7,FALSE),Tabela2[[#This Row],[STATUS_original]]) -> DISTRATO
A48: 330018/001076/2021 | B48: =IFERROR(VLOOKUP(TRIM(A48),[1]Medições!$B$2:$I$48,8,FALSE),VLOOKUP(TRIM(A48),[1]PROBLEMAS!$B$2:$I$122,8,FALSE)) -> GISELLE G. FONSECA | C48: =VLOOKUP(TRIM(Tabela2[[#This Row],[SEI]]),Tabela3[[Processo SEI]:[Objeto]],5,FALSE) -> MACRODRENAGEM DO CANAL VASQUINHO – DUQUE DE CAXIAS/RJ | D48: HYDRA | E48: DUQUE DE CAXIAS | F48: LUCIANA POSTIÇO / ARLINDO BASILIO | G48: CONCLUIDA | H48: BX | I48: =IFERROR(VLOOKUP(TRIM(Tabela2[[#This Row],[SEI]]),[1]Medições!$B$2:$H$48,7,FALSE),Tabela2[[#This Row],[STATUS_original]]) -> CONCLUIDA
A49: 170026/000122/2022 | B49: =IFERROR(VLOOKUP(TRIM(A49),[1]Medições!$B$2:$I$48,8,FALSE),VLOOKUP(TRIM(A49),[1]PROBLEMAS!$B$2:$I$122,8,FALSE)) -> GISELLE G. FONSECA | C49: =VLOOKUP(TRIM(Tabela2[[#This Row],[SEI]]),Tabela3[[Processo SEI]:[Objeto]],5,FALSE) -> PAVIMENTAÇÃO, DRENAGEM E PONTE NA ESTRADA TIRADENTES – PARAÍBA DO SUL/RJ | D49: HJ RODRIGUES | E49: PARAÍBA DO SUL | F49: NICHOLAS TAVARES / MAURÍCIO | G49: CONCLUIDA | H49: BX | I49: =IFERROR(VLOOKUP(TRIM(Tabela2[[#This Row],[SEI]]),[1]Medições!$B$2:$H$48,7,FALSE),Tabela2[[#This Row],[STATUS_original]]) -> CONCLUIDA
A50: 170026/001549/2020 | B50: =IFERROR(VLOOKUP(TRIM(A50),[1]Medições!$B$2:$I$48,8,FALSE),VLOOKUP(TRIM(A50),[1]PROBLEMAS!$B$2:$I$122,8,FALSE)) -> GISELLE G. FONSECA | C50: =VLOOKUP(TRIM(Tabela2[[#This Row],[SEI]]),Tabela3[[Processo SEI]:[Objeto]],5,FALSE) -> REVITALIZAÇÃO DAS PRAÇAS CURUPAITI, BREJAL E BELA VISTA - PARAÍBA DO SUL/RJ | D50: ABBM | E50: PARAÍBA DO SUL | F50: NICHOLAS TAVARES / MAURÍCIO | G50: CONCLUIDA | H50: BX | I50: =IFERROR(VLOOKUP(TRIM(Tabela2[[#This Row],[SEI]]),[1]Medições!$B$2:$H$48,7,FALSE),Tabela2[[#This Row],[STATUS_original]]) -> CONCLUIDA
A51: 170026/000318/2022 | B51: =IFERROR(VLOOKUP(TRIM(A51),[1]Medições!$B$2:$I$48,8,FALSE),VLOOKUP(TRIM(A51),[1]PROBLEMAS!$B$2:$I$122,8,FALSE)) -> GISELLE G. FONSECA | C51: =VLOOKUP(TRIM(Tabela2[[#This Row],[SEI]]),Tabela3[[Processo SEI]:[Objeto]],5,FALSE) -> CANALIZAÇÃO DO CANAL DO LEITÃO - MANGARATIBA/RJ | D51: LYTORANEA | E51: MANGARATIBA | F51: ARLINDO BASILIO / OTAVIO FEITOSA | G51: SUSPENSA | H51: BX | I51: =IFERROR(VLOOKUP(TRIM(Tabela2[[#This Row],[SEI]]),[1]Medições!$B$2:$H$48,7,FALSE),Tabela2[[#This Row],[STATUS_original]]) -> SUSPENSA
A52: 330018/001363/2022 | B52: =IFERROR(VLOOKUP(TRIM(A52),[1]Medições!$B$2:$I$48,8,FALSE),VLOOKUP(TRIM(A52),[1]PROBLEMAS!$B$2:$I$122,8,FALSE)) -> GISELLE G. FONSECA | C52: =VLOOKUP(TRIM(Tabela2[[#This Row],[SEI]]),Tabela3[[Processo SEI]:[Objeto]],5,FALSE) -> RECUPERAÇÃO DE PAVIMENTAÇÃO E SINALIZAÇÃO EM DUQUE DE CAXIAS | D52: MJRE | E52: DUQUE DE CAXIAS | F52: LUCIANA POSTIÇO / OSVALDO NETO | G52: ACEITE PROVISORIO | H52: BX | I52: =IFERROR(VLOOKUP(TRIM(Tabela2[[#This Row],[SEI]]),[1]Medições!$B$2:$H$48,7,FALSE),Tabela2[[#This Row],[STATUS_original]]) -> ACEITE PROVISORIO
A53: 330018/001141/2022 | B53: =IFERROR(VLOOKUP(TRIM(A53),[1]Medições!$B$2:$I$48,8,FALSE),VLOOKUP(TRIM(A53),[1]PROBLEMAS!$B$2:$I$122,8,FALSE)) -> GISELLE G. FONSECA | C53: =VLOOKUP(TRIM(Tabela2[[#This Row],[SEI]]),Tabela3[[Processo SEI]:[Objeto]],5,FALSE) -> DRENAGEM PLUVIAL E PAVIMENTAÇÃO NO BAIRRO VALDARIOSA – QUEIMADOS/RJ | D53: LYTORANEA | E53: QUEIMADOS | F53: LUCIANA POSTIÇO / NICHOLAS TAVARES | G53: ACEITE PROVISORIO | H53: BX | I53: =IFERROR(VLOOKUP(TRIM(Tabela2[[#This Row],[SEI]]),[1]Medições!$B$2:$H$48,7,FALSE),Tabela2[[#This Row],[STATUS_original]]) -> ACEITE PROVISORIO
A54: 330018/000730/2021 | B54: =IFERROR(VLOOKUP(TRIM(A54),[1]Medições!$B$2:$I$48,8,FALSE),VLOOKUP(TRIM(A54),[1]PROBLEMAS!$B$2:$I$122,8,FALSE)) -> GISELLE G. FONSECA | C54: =VLOOKUP(TRIM(Tabela2[[#This Row],[SEI]]),Tabela3[[Processo SEI]:[Objeto]],5,FALSE) -> URBANIZAÇÃO DAS ÁREAS LINDEIRAS AO RIO CAMORIM – QUEIMADOS/RJ | D54: MONJARDIN | E54: QUEIMADOS | F54: LUCIANA POSTIÇO / NICHOLAS TAVARES | G54: ACEITE DEFINITIVO | H54: BX | I54: =IFERROR(VLOOKUP(TRIM(Tabela2[[#This Row],[SEI]]),[1]Medições!$B$2:$H$48,7,FALSE),Tabela2[[#This Row],[STATUS_original]]) -> ACEITE DEFINITIVO
A55: 170026/001967/2021 | B55: =IFERROR(VLOOKUP(TRIM(A55),[1]Medições!$B$2:$I$48,8,FALSE),VLOOKUP(TRIM(A55),[1]PROBLEMAS!$B$2:$I$122,8,FALSE)) -> GISELLE G. FONSECA | C55: =VLOOKUP(TRIM(Tabela2[[#This Row],[SEI]]),Tabela3[[Processo SEI]:[Objeto]],5,FALSE) -> PAVIMENTAÇÃO E DRENAGEM – ESTRADA RIO DAS PEDRAS – RIO CLARO-RJ | D55: NF | E55: RIO CLARO | F55: NICHOLAS TAVARES | G55: DISTRATO | H55: BX | I55: =IFERROR(VLOOKUP(TRIM(Tabela2[[#This Row],[SEI]]),[1]Medições!$B$2:$H$48,7,FALSE),Tabela2[[#This Row],[STATUS_original]]) -> DISTRATO
... A81: 330001/001337/2025 | B81: =IFERROR(VLOOKUP(TRIM(A81),[1]Medições!$B$2:$I$48,8,FALSE),VLOOKUP(TRIM(A81),[1]PROBLEMAS!$B$2:$I$122,8,FALSE)) -> GISELLE G. FONSECA | C81: =VLOOKUP(TRIM(Tabela2[[#This Row],[SEI]]),Tabela3[[Processo SEI]:[Objeto]],5,FALSE) -> STABILIZAÇÃO DE TALUDES NA RUA URUGUAI NO BAIRRO QUITANDINHA-PETROPOLIS | D81: DRV | E81: PETROPOLIS | F81: ARLINDO BASILIO / NICHOLAS TAVARES | G81: EXECUÇÃO | H81: CONT | I81: =IFERROR(VLOOKUP(TRIM(Tabela2[[#This Row],[SEI]]),[1]Medições!$B$2:$H$48,7,FALSE),Tabela2[[#This Row],[STATUS_original]]) -> EXECUÇÃO
...

Sheet GERAL
A1: Processo SEI | B1: Municipio | C1: Nº do contrato | D1: Fase | E1: Objeto | F1: Contratada | G1: Acumulado atual (%) | H1: Valor contrato (Atual) | I1: Acumulado | J1: Saldo Atual do Contrato | K1: Ordem de Início | L1: Prazo Final
A2: 170026/003032/2021 | B2: ANGRA DOS REIS | D2: PREPARAÇÃO | E2: REVITALIZAÇÃO DO CAMPO DE FUTEBOL E PRAÇA - CAMPO BELO, ANGRA DOS REIS/RJ | F2: Não existe na tabela Contratadas | G2: 0 | H2: 0 | I2: 0 | J2: 0 | K2: - | L2: -
A3: 170026/001374/2022 | B3: ANGRA DOS REIS | C3: 085/2022 | D3: CONCLUÍDA | E3: CONTENÇÃO E DRENAGEM - ILHA DO ARROZ, ANGRA DOS REIS/RJ | F3: BARRA NOVA ENGENHARIA LTDA | G3: 0.8916 | H3: 14782912 | I3: 13180256 | J3: 1602655.6 | K3: 44917 | L3: 45513
A4: 330018/000445/2023 | B4: ANGRA DOS REIS | C4: 003/2024 | D4: NÃO CONCLUÍDA | E4: RECOMPOSIÇÃO DA AV. BEIRA RIO - ANGRA DOS REIS/RJ | F4: OMEGA CONSTRUTORA E SERVICOS LTDA | G4: 0 | H4: 10134015 | I4: 0 | J4: 10134015 | K4: 45365 | L4: 45476
A5: 170026/001848/2022 | B5: ANGRA DOS REIS | C5: 064/2022 | D5: CONCLUÍDA | E5: CONTENÇÃO E DRENAGEM - PRAIA DAS ÉGUAS, ANGRA DOS REIS/RJ | F5: GEOSONDA S/A - EM RECUPERAÇÃO JUDICIAL | G5: 0.6744 | H5: 37535913 | I5: 25313733 | J5: 12222179 | K5: 44807 | L5: 45208
A6: 330001/001313/2024 | B6: ANGRA DOS REIS | D6: PREPARAÇÃO | E6: CONTENÇÃO E DRENAGEM - AV. BERTOLDO DA SILVA JORDÃO, MONSUABA - ANGRA DOS REIS/RJ | F6: Não existe na tabela Contratadas | G6: 0 | H6: 48244681 | I6: 0 | J6: 48244681 | K6: - | L6: -
A7: 170026/003819/2021 | B7: APERIBÉ | D7: PREPARAÇÃO | E7: PAVIMENTAÇÃO NOS BAIRROS DERANES, CAETANO E SERRINHA – APERIBÉ/RJ | F7: Não existe na tabela Contratadas | G7: 0 | H7: 7000 | I7: 0 | J7: 7000 | K7: - | L7: -
A8: 170026/002911/2022 | B8: APERIBÉ | D8: PREPARAÇÃO | E8: REFORMA DE PRÉDIO PARA CENTRO CULTURAL – APERIBÉ/RJ | F8: Não existe na tabela Contratadas | G8: 0 | H8: 2344484.9 | I8: 0 | J8: 2344484.9 | K8: - | L8: -
A9: 330001/001445/2024 | B9: APERIBÉ | D9: CONTRATAÇÃO (FASE INTERNA) | E9: REFORMA E ADEQUAÇÃO DO CENTRO CULTURAL – APERIBÉ/RJ | F9: Não existe na tabela Contratadas | G9: 0 | H9: 2570394.1 | I9: 0 | J9: 2570394.1 | K9: - | L9: -
A10: 170026/003264/2021 | B10: ARARUAMA | C10: 023/2022 | D10: CONCLUÍDA | E10: CONSTRUÇÃO DE ACOSTAMENTO, CICLOVIA E CALÇADA EM PRAIA SECA – ARARUAMA/RJ | F10: OMEGA CONSTRUTORA E SERVICOS LTDA | G10: 1 | H10: 4928388.1 | I10: 4928388.3 | J10: -0.17 | K10: 45478 | L10: 45327
A11: 170026/000477/2022 | B11: ARARUAMA | D11: PREPARAÇÃO | E11: PAVIMENTAÇÃO, URBANIZAÇÃO E DRENAGEM EM PARATY E FAZENDINHA – ARARUAMA/RJ | F11: Não existe na tabela Contratadas | G11: 0 | H11: 0 | I11: 0 | J11: 0 | K11: - | L11: -
A12: 170026/002945/2021 | B12: ARARUAMA | D12: PREPARAÇÃO | E12: DRENAGEM, PAVIMENTAÇÃO E URBANIZAÇÃO NA AV. DO CONTORNO E RUAS ADJACENTES – IGUABINHA, ARARUAMA/RJ | F12: Não existe na tabela Contratadas | G12: 0 | H12: 0 | I12: 0 | J12: 0 | K12: - | L12: -
A13: 170026/002953/2021 | B13: ARARUAMA | D13: PREPARAÇÃO | E13: CONSTRUÇÃO DE QUADRA POLIESPORTIVA NA ESCOLA VEREADOR MOYSÉS RAMALHO – ARARUAMA/RJ | F13: Não existe na tabela Contratadas | G13: 0 | H13: 0 | I13: 0 | J13: 0 | K13: - | L13: -
A14: 330001/000487/2025 | B14: ARARUAMA | D14: PREPARAÇÃO | E14: DRENAGEM E PAVIMENTAÇÃO NA FAZENDINHA | F14: Não existe na tabela Contratadas | G14: 0 | H14: 0 | I14: 0 | J14: 0 | K14: - | L14: -
A15: 170026/002950/2021 | B15: ARARUAMA | D15: PREPARAÇÃO | E15: CONSTRUÇÃO DE QUADRA POLIESPORTIVA NA ESCOLA CELINA MESQUITA PEDROSA – ARARUAMA/RJ | F15: Não existe na tabela Contratadas | G15: 0 | H15: 1283313.1 | I15: 0 | J15: 1283313.1 | K15: - | L15: -
A16: 170026/002066/2021 | B16: ARARUAMA | D16: PREPARAÇÃO | E16: DRENAGEM, PAVIMENTAÇÃO E URBANIZAÇÃO NA RUA OSCAR CLARK – FONTE LIMPA, ARARUAMA/RJ | F16: Não existe na tabela Contratadas | G16: 0 | H16: 2730917.6 | I16: 0 | J16: 2730917.6 | K16: - | L16: -
A17: 170026/001780/2022 | B17: ARARUAMA | D17: CONTRATAÇÃO (FASE INTERNA) | E17: PAVIMENTAÇÃO E DRENAGEM EM DIVERSAS VIAS DO 3º DISTRITO – ARARUAMA/RJ | F17: Não existe na tabela Contratadas | G17: 0 | H17: 25583969 | I17: 0 | J17: 25583969 | K17: - | L17: -
A18: 330001/001549/2025 | B18: ARARUAMA | D18: CONTRATAÇÃO (FASE INTERNA) | E18: ELABORAÇÃO DE PROJETO EXECUTIVO E REALIZAÇÃO DOS SERVIÇOS DE DRENAGEM, PAVIMENTAÇÃO, SINALIZAÇÃO HORIZONTAL E CALÇADA, NO BAIRRO FAZENDINHA (BACIA 2), NO MUNICÍPIO DE ARARUAMA/RJ. | F18: Não existe na tabela Contratadas | G18: 0 | H18: 67886819 | I18: 0 | J18: 67886819 | K18: - | L18: -
A19: 330001/001564/2025 | B19: ARARUAMA | D19: PREPARAÇÃO | E19: ELABORAÇÃO DE PROJETO EXECUTIVO E REALIZAÇÃO DOS SERVIÇOS DE DRENAGEM, PAVIMENTAÇÃO, SINALIZAÇÃO HORIZONTAL E CALÇADA, NO BAIRRO FAZENDINHA (BACIAS 1 E 3), NO MUNICÍPIO DE ARARUAMA/RJ. | F19: Não existe na tabela Contratadas | G19: 0 | H19: 71876187 | I19: 0 | J19: 71876187 | K19: - | L19: -
A20: 170026/000814/2021 | B20: AREAL | C20: 025/2021 | D20: TRANSFERIDA | E20: OBRAS DE INFRAESTRUTURA E MELHORIA VIÁRIA EM AREAL/RJ | F20: CONSTRUTORA MEDEIROS CARVALHO DE ALMEIDA EIRELI | G20: 0 | H20: 4473797.8 | I20: 0 | J20: 4473797.8 | K20: 44520 | L20: -
A21: 330001/001542/2025 | B21: AREAL | D21: CONTRATAÇÃO (FASE INTERNA) | E21: CONTRATAÇÃO DE EMPRESA ESPECIALIZADA PARA EXECUÇÃO DE OBRAS PARA ADEQUAÇÃO DE ACESSOS VIÁRIOS NO MUNICÍPIO DE AREAL/RJ | F21: Não existe na tabela Contratadas | G21: 0 | H21: 5124881.8 | I21: 0 | J21: 5124881.8 | K21: - | L21: -
A22: 170026/000278/2021 | B22: ARMAÇÃO DOS BÚZIOS | D22: PREPARAÇÃO | E22: CONSTRUÇÃO DO COLÉGIO ESTADUAL PROFESSOR FRANCISCO MARIA DE SOUZA - BÚZIOS/RJ | F22: Não existe na tabela Contratadas | G22: 0 | H22: 11806978 | I22: 0 | J22: 11806978 | K22: - | L22: -
A23: 330018/001612/2022 | B23: ARMAÇÃO DOS BÚZIOS | D23: TRANSFERIDA | E23: PAVIMENTAÇÃO, DRENAGEM, SINALIZAÇÃO E ILUMINAÇÃO NA ESTRADA DA FAZENDINHA – BÚZIOS/RJ | F23: CONSORCIO FACHADA MIS R2X/TANGRAN (CONSTRUTORA R2X E TANGRAN ENGENHARIA) | G23: 0 | H23: 27621068 | I23: 0 | J23: 27621068 | K23: - | L23: -
A24: 330001/001910/2024 | B24: BARRA DO PIRAÍ | D24: PREPARAÇÃO | E24: CONTENÇÃO DE TALUDE – BAIRROS AREAL E BOA SORTE – BARRA DO PIRAÍ-RJ | F24: Não existe na tabela Contratadas | G24: 0 | H24: 11230.35 | I24: 0 | J24: 11230.35 | K24: - | L24: -
A25: 170026/000511/2022 | B25: BARRA DO PIRAÍ | D25: PREPARAÇÃO | E25: REFORMA DE PRAÇA – BAIRRO OFICINAS VELHAS – BARRA DO PIRAÍ-RJ | F25: Não existe na tabela Contratadas | G25: 0 | H25: 556051.81 | I25: 0 | J25: 556051.81 | K25: - | L25: -
A26: 170026/000516/2022 | B26: BARRA DO PIRAÍ | D26: PREPARAÇÃO | E26: CONSTRUÇÃO DA PRAÇA NO NOVO CONJUNTO HABITACIONAL, VAGEM ALEGRE, BARRA DO PIRAÍ | F26: Não existe na tabela Contratadas | G26: 0 | H26: 1028513.4 | I26: 0 | J26: 1028513.4 | K26: - | L26: -
A27: 170026/000515/2022 | B27: BARRA DO PIRAÍ | D27: PREPARAÇÃO | E27: REFORMA DA PRAÇA – VARGEM ALEGRE – BARRA DO PIRAÍ-RJ | F27: Não existe na tabela Contratadas | G27: 0 | H27: 1167726.2 | I27: 0 | J27: 1167726.2 | K27: - | L27: -
A28: 170026/000513/2022 | B28: BARRA DO PIRAÍ | D28: PREPARAÇÃO | E28: REFORMA DA PRAÇA PEDRO CUNHA – CENTRO – BARRA DO PIRAÍ-RJ | F28: Não existe na tabela Contratadas | G28: 0 | H28: 3722694.3 | I28: 0 | J28: 3722694.3 | K28: - | L28: -
A29: 170026/000514/2022 | B29: BARRA DO PIRAÍ | D29: PREPARAÇÃO | E29: REFORMA DAS PRAÇAS E CAMPOS NA RUA PRESIDENTE COSTA E SILVA, CALIFÓRNIA, BARRA DO PIRAÍ-RJ | F29: Não existe na tabela Contratadas | G29: 0 | H29: 4868256.2 | I29: 0 | J29: 4868256.2 | K29: - | L29: -
A30: 170026/001999/2022 | B30: BARRA DO PIRAÍ | D30: PREPARAÇÃO | E30: REFORMA DO CIEP 428 PROFESSORA MARIANA COELHO, VARGEM ALEGRE, BARRA DO PIRAÍ-RJ | F30: Não existe na tabela Contratadas | G30: 0 | H30: 5578284.2 | I30: 0 | J30: 5578284.2 | K30: - | L30: -
A31: 170026/001998/2022 | B31: BARRA DO PIRAÍ | D31: PREPARAÇÃO | E31: REFORMA DO CIEP 284 – DISTRITO DA CALIFÓRNIA – BARRA DO PIRAÍ-RJ | F31: Não existe na tabela Contratadas | G31: 0 | H31: 5922938.9 | I31: 0 | J31: 5922938.9 | K31: - | L31: -
A32: 170026/000517/2022 | B32: BARRA DO PIRAÍ | D32: PREPARAÇÃO | E32: CONTRATAÇÃO DE EMPRESA PARA ELABORAÇÃO E EXECUÇÃO DE PROJETOS E OBRAS DE CALÇADAS NO CENTRO DE BARRA DO PIRAÍ | F32: Não existe na tabela Contratadas | G32: 0 | H32: 6373265.8 | I32: 0 | J32: 6373265.8 | K32: - | L32: -
A33: 330001/001080/2025 | B33: BARRA DO PIRAÍ | C33: 014/2025 | D33: EXECUÇÃO | E33: REVESTIMENTO ASFÁLTICO, DRENAGEM, CONSTRUÇÃO DE GALERIAS DE ÁGUAS PLUVIAIS, URBANIZAÇÃO, CICLOFAIXA E ESTABILIZAÇÃO DE TALUDE, MUNICÍPIO DE BARRA DO PIRAÍ - RJJ | F33: CONSTRUTORA AXIAL LTDA | G33: 0.2004 | H33: 18990163 | I33: 3806174.7 | J33: 15183988 | K33: 45868 | L33: 46228
A34: 330018/000748/2022 | B34: BARRA DO PIRAÍ | C34: 013/2023 | D34: NÃO CONCLUÍDA | E34: REVESTIMENTO ASFÁLTICO, DRENAGEM E GALERIAS – BARRA DO PIRAÍ-RJ | F34: STATLED BRASIL CONSTRUTORA E PARTICIPACOES S.A. | G34: 0.0076 | H34: 16774604 | I34: 127835.64 | J34: 16646768 | K34: 45100 | L34: 45460
A35: 170026/003250/2021 | B35: BARRA MANSA | C35: 056/2022 | D35: EXECUÇÃO | E35: RECAPEAMENTO, PAVIMENTAÇÃO E CONTENÇÃO – BARRA MANSA-RJ | F35: CONSTRUTORA LYTORANEA S A | G35: 1 | H35: 5581731.3 | I35: 5581730.3 | J35: 1 | K35: 44777 | L35: 45348
A36: 170026/003814/2021 | B36: BARRA MANSA | D36: PREPARAÇÃO | E36: CONTENÇÃO DE TALUDE – RUA MAURO GRANATO – BARRA MANSA-RJ | F36: Não existe na tabela Contratadas | G36: 0 | H36: 1500 | I36: 0 | J36: 1500 | K36: - | L36: -
A37: 170026/001812/2021 | B37: BARRA MANSA | C37: 027/2021 | D37: CONCLUÍDA | E37: CONSTRUÇÃO DE PONTE - BARRA MANSA/RJ | F37: PREMAG - SISTEMA DE CONSTRUÇÕES LTDA | G37: 0.9902 | H37: 5312585.6 | I37: 5260332.3 | J37: 52253.31 | K37: 44536 | L37: 45289
A38: 330018/001062/2022 | B38: BARRA MANSA | C38: 063/2022 | D38: EXECUÇÃO | E38: PAVIMENTAÇÃO E DRENAGEM – AV. PRESIDENTE KENNEDY – BARRA MANSA-RJ | F38: STATLED BRASIL CONSTRUTORA I LTDA (subsidiária) | G38: 0.9713 | H38: 7795660.5 | I38: 7571952.3 | J38: 223708.17 | K38: 44909 | L38: 46144
A39: 330001/000715/2024 | B39: BARRA MANSA | C39: 005/2024 | D39: EXECUÇÃO | E39: USINAGEM, TRANSPORTE E PAVIMENTAÇÃO EM CBUQ – BARRA MANSA/RJ | F39: H J RODRIGUES MELO LTDA | G39: 0.8916 | H39: 7234583.8 | I39: 6450491.3 | J39: 784092.46 | K39: 45425 | L39: 45999
A40: 330001/001925/2025 | B40: BARRA MANSA | D40: PREPARAÇÃO | E40: DECK ÀS MARGENS DO RIO PARAÍBA DO SUL | F40: Não existe na tabela Contratadas | G40: - | H40: 1439881.5 | I40: 0 | J40: 1439881.5 | K40: - | L40: -
...
